2022-06-30 22:37:47,696 INFO: Microblog startup [in /mnt/e/microblog/app/__init__.py:44]
2022-06-30 22:53:48,904 INFO: Microblog startup [in /mnt/e/microblog/app/__init__.py:44]
2022-06-30 22:54:20,815 INFO: Microblog startup [in /mnt/e/microblog/app/__init__.py:44]
2022-07-08 15:33:35,393 INFO: Microblog startup [in /mnt/e/microblog/app/__init__.py:44]
2022-07-08 15:36:07,118 INFO: Microblog startup [in /mnt/e/microblog/app/__init__.py:44]
2022-07-08 15:37:27,263 INFO: Microblog startup [in /mnt/e/microblog/app/__init__.py:44]
2022-07-08 15:37:47,698 INFO: Microblog startup [in /mnt/e/microblog/app/__init__.py:44]
2022-07-08 15:43:38,657 INFO: Microblog startup [in /mnt/e/microblog/app/__init__.py:44]
2022-07-08 15:44:51,321 INFO: Microblog startup [in /mnt/e/microblog/app/__init__.py:44]
2022-07-08 15:45:02,426 INFO: Microblog startup [in /mnt/e/microblog/app/__init__.py:44]
2022-07-08 16:04:29,842 INFO: Microblog startup [in /mnt/e/microblog/app/__init__.py:44]
2022-07-08 16:04:48,648 ERROR: Exception on /user/tim [GET] [in /mnt/e/microblog/venv/lib/python3.8/site-packages/flask/app.py:1455]
Traceback (most recent call last):
  File "/mnt/e/microblog/venv/lib/python3.8/site-packages/flask/app.py", line 2077, in wsgi_app
    response = self.full_dispatch_request()
  File "/mnt/e/microblog/venv/lib/python3.8/site-packages/flask/app.py", line 1525, in full_dispatch_request
    rv = self.handle_user_exception(e)
  File "/mnt/e/microblog/venv/lib/python3.8/site-packages/flask/app.py", line 1523, in full_dispatch_request
    rv = self.dispatch_request()
  File "/mnt/e/microblog/venv/lib/python3.8/site-packages/flask/app.py", line 1509, in dispatch_request
    return self.ensure_sync(self.view_functions[rule.endpoint])(**req.view_args)
  File "/mnt/e/microblog/venv/lib/python3.8/site-packages/flask_login/utils.py", line 303, in decorated_view
    return current_app.ensure_sync(func)(*args, **kwargs)
  File "/mnt/e/microblog/app/routes.py", line 77, in user
    return render_template('user.html', user=user, posts=posts)
  File "/mnt/e/microblog/venv/lib/python3.8/site-packages/flask/templating.py", line 148, in render_template
    return _render(
  File "/mnt/e/microblog/venv/lib/python3.8/site-packages/flask/templating.py", line 128, in _render
    rv = template.render(context)
  File "/mnt/e/microblog/venv/lib/python3.8/site-packages/jinja2/environment.py", line 1301, in render
    self.environment.handle_exception()
  File "/mnt/e/microblog/venv/lib/python3.8/site-packages/jinja2/environment.py", line 936, in handle_exception
    raise rewrite_traceback_stack(source=source)
  File "/mnt/e/microblog/app/templates/user.html", line 1, in top-level template code
    {% extends "base.html" %}
  File "/mnt/e/microblog/app/templates/base.html", line 30, in top-level template code
    {% block content %}{% endblock %}
  File "/mnt/e/microblog/app/templates/user.html", line 12, in block 'content'
    <p>{{ user.followers.count() }} followers, {{ user.followed.count() }} following.</p>
TypeError: count() takes exactly one argument (0 given)
2022-07-08 16:04:52,762 ERROR: Exception on /user/tim [GET] [in /mnt/e/microblog/venv/lib/python3.8/site-packages/flask/app.py:1455]
Traceback (most recent call last):
  File "/mnt/e/microblog/venv/lib/python3.8/site-packages/flask/app.py", line 2077, in wsgi_app
    response = self.full_dispatch_request()
  File "/mnt/e/microblog/venv/lib/python3.8/site-packages/flask/app.py", line 1525, in full_dispatch_request
    rv = self.handle_user_exception(e)
  File "/mnt/e/microblog/venv/lib/python3.8/site-packages/flask/app.py", line 1523, in full_dispatch_request
    rv = self.dispatch_request()
  File "/mnt/e/microblog/venv/lib/python3.8/site-packages/flask/app.py", line 1509, in dispatch_request
    return self.ensure_sync(self.view_functions[rule.endpoint])(**req.view_args)
  File "/mnt/e/microblog/venv/lib/python3.8/site-packages/flask_login/utils.py", line 303, in decorated_view
    return current_app.ensure_sync(func)(*args, **kwargs)
  File "/mnt/e/microblog/app/routes.py", line 77, in user
    return render_template('user.html', user=user, posts=posts)
  File "/mnt/e/microblog/venv/lib/python3.8/site-packages/flask/templating.py", line 148, in render_template
    return _render(
  File "/mnt/e/microblog/venv/lib/python3.8/site-packages/flask/templating.py", line 128, in _render
    rv = template.render(context)
  File "/mnt/e/microblog/venv/lib/python3.8/site-packages/jinja2/environment.py", line 1301, in render
    self.environment.handle_exception()
  File "/mnt/e/microblog/venv/lib/python3.8/site-packages/jinja2/environment.py", line 936, in handle_exception
    raise rewrite_traceback_stack(source=source)
  File "/mnt/e/microblog/app/templates/user.html", line 1, in top-level template code
    {% extends "base.html" %}
  File "/mnt/e/microblog/app/templates/base.html", line 30, in top-level template code
    {% block content %}{% endblock %}
  File "/mnt/e/microblog/app/templates/user.html", line 12, in block 'content'
    <p>{{ user.followers.count() }} followers, {{ user.followed.count() }} following.</p>
TypeError: count() takes exactly one argument (0 given)
2022-07-08 16:04:55,858 ERROR: Exception on /user/tim [GET] [in /mnt/e/microblog/venv/lib/python3.8/site-packages/flask/app.py:1455]
Traceback (most recent call last):
  File "/mnt/e/microblog/venv/lib/python3.8/site-packages/flask/app.py", line 2077, in wsgi_app
    response = self.full_dispatch_request()
  File "/mnt/e/microblog/venv/lib/python3.8/site-packages/flask/app.py", line 1525, in full_dispatch_request
    rv = self.handle_user_exception(e)
  File "/mnt/e/microblog/venv/lib/python3.8/site-packages/flask/app.py", line 1523, in full_dispatch_request
    rv = self.dispatch_request()
  File "/mnt/e/microblog/venv/lib/python3.8/site-packages/flask/app.py", line 1509, in dispatch_request
    return self.ensure_sync(self.view_functions[rule.endpoint])(**req.view_args)
  File "/mnt/e/microblog/venv/lib/python3.8/site-packages/flask_login/utils.py", line 303, in decorated_view
    return current_app.ensure_sync(func)(*args, **kwargs)
  File "/mnt/e/microblog/app/routes.py", line 77, in user
    return render_template('user.html', user=user, posts=posts)
  File "/mnt/e/microblog/venv/lib/python3.8/site-packages/flask/templating.py", line 148, in render_template
    return _render(
  File "/mnt/e/microblog/venv/lib/python3.8/site-packages/flask/templating.py", line 128, in _render
    rv = template.render(context)
  File "/mnt/e/microblog/venv/lib/python3.8/site-packages/jinja2/environment.py", line 1301, in render
    self.environment.handle_exception()
  File "/mnt/e/microblog/venv/lib/python3.8/site-packages/jinja2/environment.py", line 936, in handle_exception
    raise rewrite_traceback_stack(source=source)
  File "/mnt/e/microblog/app/templates/user.html", line 1, in top-level template code
    {% extends "base.html" %}
  File "/mnt/e/microblog/app/templates/base.html", line 30, in top-level template code
    {% block content %}{% endblock %}
  File "/mnt/e/microblog/app/templates/user.html", line 12, in block 'content'
    <p>{{ user.followers.count() }} followers, {{ user.followed.count() }} following.</p>
TypeError: count() takes exactly one argument (0 given)
2022-07-08 16:05:11,281 ERROR: Exception on /user/tim [GET] [in /mnt/e/microblog/venv/lib/python3.8/site-packages/flask/app.py:1455]
Traceback (most recent call last):
  File "/mnt/e/microblog/venv/lib/python3.8/site-packages/flask/app.py", line 2077, in wsgi_app
    response = self.full_dispatch_request()
  File "/mnt/e/microblog/venv/lib/python3.8/site-packages/flask/app.py", line 1525, in full_dispatch_request
    rv = self.handle_user_exception(e)
  File "/mnt/e/microblog/venv/lib/python3.8/site-packages/flask/app.py", line 1523, in full_dispatch_request
    rv = self.dispatch_request()
  File "/mnt/e/microblog/venv/lib/python3.8/site-packages/flask/app.py", line 1509, in dispatch_request
    return self.ensure_sync(self.view_functions[rule.endpoint])(**req.view_args)
  File "/mnt/e/microblog/venv/lib/python3.8/site-packages/flask_login/utils.py", line 303, in decorated_view
    return current_app.ensure_sync(func)(*args, **kwargs)
  File "/mnt/e/microblog/app/routes.py", line 77, in user
    return render_template('user.html', user=user, posts=posts)
  File "/mnt/e/microblog/venv/lib/python3.8/site-packages/flask/templating.py", line 148, in render_template
    return _render(
  File "/mnt/e/microblog/venv/lib/python3.8/site-packages/flask/templating.py", line 128, in _render
    rv = template.render(context)
  File "/mnt/e/microblog/venv/lib/python3.8/site-packages/jinja2/environment.py", line 1301, in render
    self.environment.handle_exception()
  File "/mnt/e/microblog/venv/lib/python3.8/site-packages/jinja2/environment.py", line 936, in handle_exception
    raise rewrite_traceback_stack(source=source)
  File "/mnt/e/microblog/app/templates/user.html", line 1, in top-level template code
    {% extends "base.html" %}
  File "/mnt/e/microblog/app/templates/base.html", line 30, in top-level template code
    {% block content %}{% endblock %}
  File "/mnt/e/microblog/app/templates/user.html", line 12, in block 'content'
    <p>{{ user.followers.count() }} followers, {{ user.followed.count() }} following.</p>
TypeError: count() takes exactly one argument (0 given)
2022-07-08 16:07:29,509 INFO: Microblog startup [in /mnt/e/microblog/app/__init__.py:44]
