2022-07-08 16:07:33,869 ERROR: Exception on /user/tim [GET] [in /mnt/e/microblog/venv/lib/python3.8/site-packages/flask/app.py:1455]
Traceback (most recent call last):
  File "/mnt/e/microblog/venv/lib/python3.8/site-packages/flask/app.py", line 2077, in wsgi_app
    response = self.full_dispatch_request()
  File "/mnt/e/microblog/venv/lib/python3.8/site-packages/flask/app.py", line 1525, in full_dispatch_request
    rv = self.handle_user_exception(e)
  File "/mnt/e/microblog/venv/lib/python3.8/site-packages/flask/app.py", line 1523, in full_dispatch_request
    rv = self.dispatch_request()
  File "/mnt/e/microblog/venv/lib/python3.8/site-packages/flask/app.py", line 1509, in dispatch_request
    return self.ensure_sync(self.view_functions[rule.endpoint])(**req.view_args)
  File "/mnt/e/microblog/venv/lib/python3.8/site-packages/flask_login/utils.py", line 303, in decorated_view
    return current_app.ensure_sync(func)(*args, **kwargs)
  File "/mnt/e/microblog/app/routes.py", line 77, in user
    return render_template('user.html', user=user, posts=posts)
  File "/mnt/e/microblog/venv/lib/python3.8/site-packages/flask/templating.py", line 148, in render_template
    return _render(
  File "/mnt/e/microblog/venv/lib/python3.8/site-packages/flask/templating.py", line 128, in _render
    rv = template.render(context)
  File "/mnt/e/microblog/venv/lib/python3.8/site-packages/jinja2/environment.py", line 1301, in render
    self.environment.handle_exception()
  File "/mnt/e/microblog/venv/lib/python3.8/site-packages/jinja2/environment.py", line 936, in handle_exception
    raise rewrite_traceback_stack(source=source)
  File "/mnt/e/microblog/app/templates/user.html", line 1, in top-level template code
    {% extends "base.html" %}
  File "/mnt/e/microblog/app/templates/base.html", line 30, in top-level template code
    {% block content %}{% endblock %}
  File "/mnt/e/microblog/app/templates/user.html", line 11, in block 'content'
    <p>{{ user.followers.count() }} followers, {{ user.followed.count() }} following.</p>
TypeError: count() takes exactly one argument (0 given)
2022-07-08 16:07:35,375 ERROR: Exception on /user/tim [GET] [in /mnt/e/microblog/venv/lib/python3.8/site-packages/flask/app.py:1455]
Traceback (most recent call last):
  File "/mnt/e/microblog/venv/lib/python3.8/site-packages/flask/app.py", line 2077, in wsgi_app
    response = self.full_dispatch_request()
  File "/mnt/e/microblog/venv/lib/python3.8/site-packages/flask/app.py", line 1525, in full_dispatch_request
    rv = self.handle_user_exception(e)
  File "/mnt/e/microblog/venv/lib/python3.8/site-packages/flask/app.py", line 1523, in full_dispatch_request
    rv = self.dispatch_request()
  File "/mnt/e/microblog/venv/lib/python3.8/site-packages/flask/app.py", line 1509, in dispatch_request
    return self.ensure_sync(self.view_functions[rule.endpoint])(**req.view_args)
  File "/mnt/e/microblog/venv/lib/python3.8/site-packages/flask_login/utils.py", line 303, in decorated_view
    return current_app.ensure_sync(func)(*args, **kwargs)
  File "/mnt/e/microblog/app/routes.py", line 77, in user
    return render_template('user.html', user=user, posts=posts)
  File "/mnt/e/microblog/venv/lib/python3.8/site-packages/flask/templating.py", line 148, in render_template
    return _render(
  File "/mnt/e/microblog/venv/lib/python3.8/site-packages/flask/templating.py", line 128, in _render
    rv = template.render(context)
  File "/mnt/e/microblog/venv/lib/python3.8/site-packages/jinja2/environment.py", line 1301, in render
    self.environment.handle_exception()
  File "/mnt/e/microblog/venv/lib/python3.8/site-packages/jinja2/environment.py", line 936, in handle_exception
    raise rewrite_traceback_stack(source=source)
  File "/mnt/e/microblog/app/templates/user.html", line 1, in top-level template code
    {% extends "base.html" %}
  File "/mnt/e/microblog/app/templates/base.html", line 30, in top-level template code
    {% block content %}{% endblock %}
  File "/mnt/e/microblog/app/templates/user.html", line 11, in block 'content'
    <p>{{ user.followers.count() }} followers, {{ user.followed.count() }} following.</p>
TypeError: count() takes exactly one argument (0 given)
2022-07-08 16:07:48,203 ERROR: Exception on /user/tim [GET] [in /mnt/e/microblog/venv/lib/python3.8/site-packages/flask/app.py:1455]
Traceback (most recent call last):
  File "/mnt/e/microblog/venv/lib/python3.8/site-packages/flask/app.py", line 2077, in wsgi_app
    response = self.full_dispatch_request()
  File "/mnt/e/microblog/venv/lib/python3.8/site-packages/flask/app.py", line 1525, in full_dispatch_request
    rv = self.handle_user_exception(e)
  File "/mnt/e/microblog/venv/lib/python3.8/site-packages/flask/app.py", line 1523, in full_dispatch_request
    rv = self.dispatch_request()
  File "/mnt/e/microblog/venv/lib/python3.8/site-packages/flask/app.py", line 1509, in dispatch_request
    return self.ensure_sync(self.view_functions[rule.endpoint])(**req.view_args)
  File "/mnt/e/microblog/venv/lib/python3.8/site-packages/flask_login/utils.py", line 303, in decorated_view
    return current_app.ensure_sync(func)(*args, **kwargs)
  File "/mnt/e/microblog/app/routes.py", line 77, in user
    return render_template('user.html', user=user, posts=posts)
  File "/mnt/e/microblog/venv/lib/python3.8/site-packages/flask/templating.py", line 148, in render_template
    return _render(
  File "/mnt/e/microblog/venv/lib/python3.8/site-packages/flask/templating.py", line 128, in _render
    rv = template.render(context)
  File "/mnt/e/microblog/venv/lib/python3.8/site-packages/jinja2/environment.py", line 1301, in render
    self.environment.handle_exception()
  File "/mnt/e/microblog/venv/lib/python3.8/site-packages/jinja2/environment.py", line 936, in handle_exception
    raise rewrite_traceback_stack(source=source)
  File "/mnt/e/microblog/app/templates/user.html", line 1, in top-level template code
    {% extends "base.html" %}
  File "/mnt/e/microblog/app/templates/base.html", line 30, in top-level template code
    {% block content %}{% endblock %}
  File "/mnt/e/microblog/app/templates/user.html", line 11, in block 'content'
    <p>{{ user.followers.count() }} followers, {{ user.followed.count() }} following.</p>
TypeError: count() takes exactly one argument (0 given)
2022-07-08 16:09:37,529 INFO: Microblog startup [in /mnt/e/microblog/app/__init__.py:44]
2022-07-08 16:10:55,670 ERROR: Exception on /login [POST] [in /mnt/e/microblog/venv/lib/python3.8/site-packages/flask/app.py:1455]
Traceback (most recent call last):
  File "/mnt/e/microblog/venv/lib/python3.8/site-packages/flask/app.py", line 2077, in wsgi_app
    response = self.full_dispatch_request()
  File "/mnt/e/microblog/venv/lib/python3.8/site-packages/flask/app.py", line 1525, in full_dispatch_request
    rv = self.handle_user_exception(e)
  File "/mnt/e/microblog/venv/lib/python3.8/site-packages/flask/app.py", line 1523, in full_dispatch_request
    rv = self.dispatch_request()
  File "/mnt/e/microblog/venv/lib/python3.8/site-packages/flask/app.py", line 1509, in dispatch_request
    return self.ensure_sync(self.view_functions[rule.endpoint])(**req.view_args)
  File "/mnt/e/microblog/app/routes.py", line 40, in login
    if user is None or not user.check_password(form.password.data):
  File "/mnt/e/microblog/app/models.py", line 30, in check_password
    return check_password_hash(self.password_hash, password)
  File "/mnt/e/microblog/venv/lib/python3.8/site-packages/werkzeug/security.py", line 103, in check_password_hash
    if pwhash.count("$") < 2:
AttributeError: 'NoneType' object has no attribute 'count'
2022-07-08 16:12:21,920 INFO: Microblog startup [in /mnt/e/microblog/app/__init__.py:44]
2022-07-08 16:12:38,455 INFO: Microblog startup [in /mnt/e/microblog/app/__init__.py:44]
2022-07-08 16:14:36,486 INFO: Microblog startup [in /mnt/e/microblog/app/__init__.py:44]
2022-07-08 16:22:35,248 INFO: Microblog startup [in /mnt/e/microblog/app/__init__.py:44]
2022-07-08 16:26:08,299 INFO: Microblog startup [in /mnt/e/microblog/app/__init__.py:44]
2022-07-08 16:34:55,065 INFO: Microblog startup [in /mnt/e/microblog/app/__init__.py:44]
